Failure # 1 (occurred at 2022-05-17_17-15-30)
Traceback (most recent call last):
  File "/home/startupshell/miniconda3/envs/minerl/lib/python3.7/site-packages/ray/tune/ray_trial_executor.py", line 901, in get_next_executor_event
    future_result = ray.get(ready_future)
  File "/home/startupshell/miniconda3/envs/minerl/lib/python3.7/site-packages/ray/_private/client_mode_hook.py", line 105, in wrapper
    return func(*args, **kwargs)
  File "/home/startupshell/miniconda3/envs/minerl/lib/python3.7/site-packages/ray/worker.py", line 1811, in get
    raise value
ray.exceptions.RayActorError: The actor died because of an error raised in its creation task, [36mray::PPOTrainer.__init__()[39m (pid=27259, ip=10.104.57.75, repr=PPOTrainer)
  File "/home/startupshell/miniconda3/envs/minerl/lib/python3.7/site-packages/ray/rllib/agents/trainer.py", line 1035, in _init
    raise NotImplementedError
NotImplementedError

During handling of the above exception, another exception occurred:

[36mray::PPOTrainer.__init__()[39m (pid=27259, ip=10.104.57.75, repr=PPOTrainer)
  File "/home/startupshell/miniconda3/envs/minerl/lib/python3.7/site-packages/ray/rllib/agents/trainer.py", line 831, in __init__
    config, logger_creator, remote_checkpoint_dir, sync_function_tpl
  File "/home/startupshell/miniconda3/envs/minerl/lib/python3.7/site-packages/ray/tune/trainable.py", line 149, in __init__
    self.setup(copy.deepcopy(self.config))
  File "/home/startupshell/miniconda3/envs/minerl/lib/python3.7/site-packages/ray/rllib/agents/trainer.py", line 918, in setup
    logdir=self.logdir,
  File "/home/startupshell/miniconda3/envs/minerl/lib/python3.7/site-packages/ray/rllib/evaluation/worker_set.py", line 136, in __init__
    lambda p, pid: (pid, p.observation_space, p.action_space)
ray.exceptions.RayActorError: The actor died because of an error raised in its creation task, [36mray::RolloutWorker.__init__()[39m (pid=27326, ip=10.104.57.75, repr=<ray.rllib.evaluation.rollout_worker.RolloutWorker object at 0x7fc2e58b4610>)
  File "/home/startupshell/miniconda3/envs/minerl/lib/python3.7/site-packages/ray/rllib/evaluation/rollout_worker.py", line 507, in __init__
    check_env(self.env)
  File "/home/startupshell/miniconda3/envs/minerl/lib/python3.7/site-packages/ray/rllib/utils/pre_checks/env.py", line 63, in check_env
    check_multiagent_environments(env)
  File "/home/startupshell/miniconda3/envs/minerl/lib/python3.7/site-packages/ray/rllib/utils/pre_checks/env.py", line 197, in check_multiagent_environments
    _check_if_element_multi_agent_dict(env, reset_obs, "reset()")
  File "/home/startupshell/miniconda3/envs/minerl/lib/python3.7/site-packages/ray/rllib/utils/pre_checks/env.py", line 475, in _check_if_element_multi_agent_dict
    raise ValueError(error)
ValueError: The element returned by reset() has agent_ids that are not the names of the agents in the env. 
Agent_ids in this MultiAgentDict: ['agent_0', 'agent_1']
Agent_ids in this env:['__all__']. You likley need to add the private attribute `_agent_ids` to your env, which is a set containing the ids of agents supported by your env.

